<?xml version="1.0" ?>
<!-- This URDF was automatically created by SolidWorks to URDF Exporter! Originally created by Stephen Brawner (brawner@gmail.com) 
     Commit Version: 1.6.0-4-g7f85cfe  Build Version: 1.6.7995.38578
     For more information, please see http://wiki.ros.org/sw_urdf_exporter -->
<robot
  name="mobile_car" xmlns:xacro="http://ros.org/wiki/xacro">

  <xacro:macro name="base_link_color">
    <visual>
      <material>
        <ambient>255 0 0 1</ambient>
        <diffuse>255 0 0 1</diffuse>
        <specular>0.1 0.1 0.1 1</specular>
        <emissive>0 0 0 0</emissive>
      </material>
    </visual>
  </xacro:macro>
  <xacro:macro name="lidar_link_color">
    <visual>
      <material>
        <ambient>0 0 225 1</ambient>
        <diffuse>0 0 225 1</diffuse>
        <specular>0.1 0.1 0.1 1</specular>
        <emissive>0 0 0 0</emissive>
      </material>
    </visual>
  </xacro:macro>
  <xacro:macro name="axle_link_color">
    <visual>
      <material>
        <ambient>0 0 0 0.6</ambient>
        <diffuse>0 0 0 0.6</diffuse>
        <specular>0.1 0.1 0.1 1</specular>
        <emissive>0 0 0 0</emissive>
      </material>
    </visual>
  </xacro:macro>
  <xacro:macro name="wheel_link_color">
    <visual>
      <material>
        <ambient>0 0 0 1</ambient>
        <diffuse>0 0 0 1</diffuse>
        <specular>0.1 0.1 0.1 1</specular>
        <emissive>0 0 0 0</emissive>
      </material>
    </visual>
  </xacro:macro>

  # Add this before base link
  <link name="dummy_link"></link>

  <link
    name="base_link">
    <inertial>
      <origin
        xyz="0.010446 -0.00042509 0.16313"
        rpy="0 0 0" />
      <mass
        value="15.415" />
      <inertia
        ixx="0.21291"
        ixy="0.00016421"
        ixz="-0.010824"
        iyy="0.97098"
        iyz="0.00020671"
        izz="1.1289" />
    </inertial>
    <visual>
      <origin
        xyz="0 0 0"
        rpy="0 0 0" />
      <geometry>
        <mesh
          filename="package://mobile_car/meshes/base_link.STL" />
      </geometry>
      <material
        name="">
        <color
          rgba="0.79216 0.81961 0.93333 1" />
      </material>
    </visual>
    <collision>
      <origin
        xyz="0 0 0"
        rpy="0 0 0" />
      <geometry>
        <mesh
          filename="package://mobile_car/meshes/base_link.STL" />
      </geometry>
    </collision>
  </link>

  # Add this after base link
  <joint name="dummy_joint" type="fixed">
    <origin rpy="0 0 0" xyz="0 0 0" />
    <parent link="dummy_link"/>
    <child link="base_link"/>
  </joint>

  <link
    name="axle_link1">
    <inertial>
      <origin
        xyz="-2.3443E-08 0.034189 0.055744"
        rpy="0 0 0" />
      <mass
        value="0.33741" />
      <inertia
        ixx="0.00067039"
        ixy="-1.3884E-10"
        ixz="3.3628E-10"
        iyy="0.00061682"
        iyz="-5.2053E-06"
        izz="0.00043913" />
    </inertial>
    <visual>
      <origin
        xyz="0 0 0"
        rpy="0 0 0" />
      <geometry>
        <mesh
          filename="package://mobile_car/meshes/axle_link1.STL" />
      </geometry>
      <material
        name="">
        <color
          rgba="0.79216 0.81961 0.93333 1" />
      </material>
    </visual>
    <collision>
      <origin
        xyz="0 0 0"
        rpy="0 0 0" />
      <geometry>
        <mesh
          filename="package://mobile_car/meshes/axle_link1.STL" />
      </geometry>
    </collision>
  </link>
  <joint
    name="axle_joint1"
    type="revolute">
    <origin
      xyz="-0.26801 -0.2736 0.051"
      rpy="0 0 3.1397" />
    <parent
      link="base_link" />
    <child
      link="axle_link1" />
    <axis
      xyz="0 0 -1" />
    <limit
      lower="-0.6"
      upper="0.6"
      effort="10"
      velocity="1" />
  </joint>
  <link
    name="wheel_link1">
    <inertial>
      <origin
        xyz="-0.034286 1.5219E-06 -1.7489E-06"
        rpy="0 0 0" />
      <mass
        value="0.8084" />
      <inertia
        ixx="0.0053814"
        ixy="1.6143E-08"
        ixz="-1.8551E-08"
        iyy="0.0029763"
        iyz="4.1157E-08"
        izz="0.0029604" />
    </inertial>
    <visual>
      <origin
        xyz="0 0 0"
        rpy="0 0 0" />
      <geometry>
        <mesh
          filename="package://mobile_car/meshes/wheel_link1.STL" />
      </geometry>
      <material
        name="">
        <color
          rgba="0.79216 0.81961 0.93333 1" />
      </material>
    </visual>
    <collision>
      <origin
        xyz="0 0 0"
        rpy="0 0 0" />
      <geometry>
        <mesh
          filename="package://mobile_car/meshes/wheel_link1.STL" />
      </geometry>
    </collision>
  </link>
  <joint
    name="wheel_joint1"
    type="continuous">
    <origin
      xyz="0 0.050593 0.058981"
      rpy="0 0 -1.5708" />
    <parent
      link="axle_link1" />
    <child
      link="wheel_link1" />
    <axis
      xyz="-1 0 0" />
    <limit
      effort="300"
      velocity="10" />
  </joint>
  <link
    name="axle_link2">
    <inertial>
      <origin
        xyz="-2.3448E-08 0.034189 0.055744"
        rpy="0 0 0" />
      <mass
        value="0.33741" />
      <inertia
        ixx="0.00067039"
        ixy="-1.3888E-10"
        ixz="3.3636E-10"
        iyy="0.00061682"
        iyz="-5.2053E-06"
        izz="0.00043913" />
    </inertial>
    <visual>
      <origin
        xyz="0 0 0"
        rpy="0 0 0" />
      <geometry>
        <mesh
          filename="package://mobile_car/meshes/axle_link2.STL" />
      </geometry>
      <material
        name="">
        <color
          rgba="0.79216 0.81961 0.93333 1" />
      </material>
    </visual>
    <collision>
      <origin
        xyz="0 0 0"
        rpy="0 0 0" />
      <geometry>
        <mesh
          filename="package://mobile_car/meshes/axle_link2.STL" />
      </geometry>
    </collision>
  </link>
  <joint
    name="axle_joint2"
    type="fixed">
    <origin
      xyz="0.26801 -0.2736 0.051"
      rpy="0 0 3.1385" />
    <parent
      link="base_link" />
    <child
      link="axle_link2" />
    <axis
      xyz="0 0 -1" />
  </joint>
  <link
    name="wheel_link2">
    <inertial>
      <origin
        xyz="-0.034544 1.5219E-06 -1.7489E-06"
        rpy="0 0 0" />
      <mass
        value="0.8084" />
      <inertia
        ixx="0.0053814"
        ixy="1.6143E-08"
        ixz="-1.8551E-08"
        iyy="0.0029763"
        iyz="4.1157E-08"
        izz="0.0029604" />
    </inertial>
    <visual>
      <origin
        xyz="0 0 0"
        rpy="0 0 0" />
      <geometry>
        <mesh
          filename="package://mobile_car/meshes/wheel_link2.STL" />
      </geometry>
      <material
        name="">
        <color
          rgba="0.79216 0.81961 0.93333 1" />
      </material>
    </visual>
    <collision>
      <origin
        xyz="0 0 0"
        rpy="0 0 0" />
      <geometry>
        <mesh
          filename="package://mobile_car/meshes/wheel_link2.STL" />
      </geometry>
    </collision>
  </link>
  <joint
    name="wheel_joint2"
    type="continuous">
    <origin
      xyz="0 0.050336 0.058981"
      rpy="0 0 -1.5708" />
    <parent
      link="axle_link2" />
    <child
      link="wheel_link2" />
    <axis
      xyz="-1 0 0" />
    <limit
      effort="300"
      velocity="10" />
  </joint>
  <link
    name="axle_link3">
    <inertial>
      <origin
        xyz="-2.3457E-08 0.034189 0.055744"
        rpy="0 0 0" />
      <mass
        value="0.33741" />
      <inertia
        ixx="0.00067039"
        ixy="-1.3931E-10"
        ixz="3.3642E-10"
        iyy="0.00061682"
        iyz="-5.2053E-06"
        izz="0.00043913" />
    </inertial>
    <visual>
      <origin
        xyz="0 0 0"
        rpy="0 0 0" />
      <geometry>
        <mesh
          filename="package://mobile_car/meshes/axle_link3.STL" />
      </geometry>
      <material
        name="">
        <color
          rgba="0.79216 0.81961 0.93333 1" />
      </material>
    </visual>
    <collision>
      <origin
        xyz="0 0 0"
        rpy="0 0 0" />
      <geometry>
        <mesh
          filename="package://mobile_car/meshes/axle_link3.STL" />
      </geometry>
    </collision>
  </link>
  <joint
    name="axle_joint3"
    type="revolute">
    <origin
      xyz="-0.26801 0.2736 0.051"
      rpy="0 0 0.01392" />
    <parent
      link="base_link" />
    <child
      link="axle_link3" />
    <axis
      xyz="0 0 -1" />
    <limit
      lower="-0.6"
      upper="0.6"
      effort="10"
      velocity="1" />
  </joint>
  <link
    name="wheel_link3">
    <inertial>
      <origin
        xyz="-0.033866 1.5219E-06 -1.7489E-06"
        rpy="0 0 0" />
      <mass
        value="0.8084" />
      <inertia
        ixx="0.0053814"
        ixy="1.6143E-08"
        ixz="-1.8551E-08"
        iyy="0.0029763"
        iyz="4.1157E-08"
        izz="0.0029604" />
    </inertial>
    <visual>
      <origin
        xyz="0 0 0"
        rpy="0 0 0" />
      <geometry>
        <mesh
          filename="package://mobile_car/meshes/wheel_link3.STL" />
      </geometry>
      <material
        name="">
        <color
          rgba="0.79216 0.81961 0.93333 1" />
      </material>
    </visual>
    <collision>
      <origin
        xyz="0 0 0"
        rpy="0 0 0" />
      <geometry>
        <mesh
          filename="package://mobile_car/meshes/wheel_link3.STL" />
      </geometry>
    </collision>
  </link>
  <joint
    name="wheel_joint3"
    type="continuous">
    <origin
      xyz="0 0.051013 0.058981"
      rpy="0 0 -1.5708" />
    <parent
      link="axle_link3" />
    <child
      link="wheel_link3" />
    <axis
      xyz="-1 0 0" />
    <limit
      effort="100"
      velocity="10" />
  </joint>
  <link
    name="axle_link4">
    <inertial>
      <origin
        xyz="-2.3443E-08 0.034189 0.055744"
        rpy="0 0 0" />
      <mass
        value="0.33741" />
      <inertia
        ixx="0.00067039"
        ixy="-1.3884E-10"
        ixz="3.3629E-10"
        iyy="0.00061682"
        iyz="-5.2053E-06"
        izz="0.00043913" />
    </inertial>
    <visual>
      <origin
        xyz="0 0 0"
        rpy="0 0 0" />
      <geometry>
        <mesh
          filename="package://mobile_car/meshes/axle_link4.STL" />
      </geometry>
      <material
        name="">
        <color
          rgba="0.79216 0.81961 0.93333 1" />
      </material>
    </visual>
    <collision>
      <origin
        xyz="0 0 0"
        rpy="0 0 0" />
      <geometry>
        <mesh
          filename="package://mobile_car/meshes/axle_link4.STL" />
      </geometry>
    </collision>
  </link>
  <joint
    name="axle_joint4"
    type="fixed">
    <origin
      xyz="0.26801 0.2736 0.051"
      rpy="0 0 -0.0020094" />
    <parent
      link="base_link" />
    <child
      link="axle_link4" />
    <axis
      xyz="0 0 -1" />
  </joint>
  <link
    name="wheel_link4">
    <inertial>
      <origin
        xyz="-0.034466 1.5219E-06 -1.7489E-06"
        rpy="0 0 0" />
      <mass
        value="0.8084" />
      <inertia
        ixx="0.0053814"
        ixy="1.6143E-08"
        ixz="-1.8551E-08"
        iyy="0.0029763"
        iyz="4.1157E-08"
        izz="0.0029604" />
    </inertial>
    <visual>
      <origin
        xyz="0 0 0"
        rpy="0 0 0" />
      <geometry>
        <mesh
          filename="package://mobile_car/meshes/wheel_link4.STL" />
      </geometry>
      <material
        name="">
        <color
          rgba="0.79216 0.81961 0.93333 1" />
      </material>
    </visual>
    <collision>
      <origin
        xyz="0 0 0"
        rpy="0 0 0" />
      <geometry>
        <mesh
          filename="package://mobile_car/meshes/wheel_link4.STL" />
      </geometry>
    </collision>
  </link>
  <joint
    name="wheel_joint4"
    type="continuous">
    <origin
      xyz="0 0.050413 0.058981"
      rpy="1.0027 0 -1.5708" />
    <parent
      link="axle_link4" />
    <child
      link="wheel_link4" />
    <axis
      xyz="-1 0 0" />
    <limit
      effort="100"
      velocity="10" />
  </joint>
  <link
    name="lidar_link">
    <inertial>
      <origin
        xyz="-0.00051418 0.00036322 -0.007"
        rpy="0 0 0" />
      <mass
        value="0.0015708" />
      <inertia
        ixx="6.2177E-08"
        ixy="5.4763E-56"
        ixz="1.1029E-24"
        iyy="6.2177E-08"
        iyz="-1.5178E-40"
        izz="1.9635E-08" />
    </inertial>
    <visual>
      <origin
        xyz="0 0 0"
        rpy="0 0 0" />
      <geometry>
        <mesh
          filename="package://mobile_car/meshes/lidar_link.STL" />
      </geometry>
      <material
        name="">
        <color
          rgba="0.79216 0.81961 0.93333 1" />
      </material>
    </visual>
    <collision>
      <origin
        xyz="0 0 0"
        rpy="0 0 0" />
      <geometry>
        <mesh
          filename="package://mobile_car/meshes/lidar_link.STL" />
      </geometry>
    </collision>
  </link>
  <joint
    name="lidar_joint"
    type="fixed">
    <origin
      xyz="-0.07 0 0.38"
      rpy="0 0 0" />
    <parent
      link="base_link" />
    <child
      link="lidar_link" />
    <axis
      xyz="0 0 0" />
  </joint>

  <gazebo reference="lidar_link">
    <sensor name="lidar" type="ray">
      <pose>0.0 0.0 0.0 0 0 0</pose>
      <always_on>true</always_on>
      <visualize>true</visualize>
      <update_rate>5</update_rate>
      <ray>
        <scan>
          <horizontal>
            <samples>360</samples>
            <resolution>1.00000</resolution>
            <min_angle>0.000000</min_angle>
            <max_angle>6.280000</max_angle>
          </horizontal>
        </scan>
        <range>
          <min>0.120000</min>
          <max>3.5</max>
          <resolution>0.015000</resolution>
        </range>
        <noise>
          <type>gaussian</type>
          <mean>0.0</mean>
          <stddev>0.01</stddev>
        </noise>
      </ray>
      <plugin name="scan" filename="libgazebo_ros_ray_sensor.so">
        <ros>
          <remapping>~/out:=scan</remapping>
        </ros>
        <output_type>sensor_msgs/LaserScan</output_type>
        <frame_name>lidar_link</frame_name>
      </plugin>
    </sensor>
  </gazebo>

  <gazebo reference="base_link">
    <gravity>true</gravity>
    <sensor name="imu_sensor" type="imu">
      <always_on>true</always_on>
      <update_rate>100</update_rate>
      <visualize>true</visualize>
      <topic>__default_topic__</topic>
      <plugin filename="libgazebo_ros_imu_sensor.so" name="imu_plugin">
        <topicName>imu</topicName>
        <bodyName>base_link</bodyName>
        <updateRateHZ>10.0</updateRateHZ>
        <gaussianNoise>0.0</gaussianNoise>
        <xyzOffset>0 0 0</xyzOffset>
        <rpyOffset>0 0 0</rpyOffset>
        <frameName>base_link</frameName>
        <initialOrientationAsReference>false</initialOrientationAsReference>
      </plugin>
      <pose>0 0 0 0 0 0</pose>
    </sensor>
  </gazebo>

  <ros2_control name="GazeboSystem" type="system">
    <hardware>
      <plugin>gazebo_ros2_control/GazeboSystem</plugin>
    </hardware>
    # Velocity Controllers

    <joint name="wheel_joint1">
      <command_interface name="velocity">
        <param name="min">-10.0</param>
        <param name="max">10.0</param>
      </command_interface>
      <state_interface name="position"/>
      <state_interface name="velocity"/>
    </joint>
    <joint name="wheel_joint2">
      <command_interface name="velocity">
        <param name="min">-10.0</param>
        <param name="max">10.0</param>
      </command_interface>
      <state_interface name="position"/>
      <state_interface name="velocity"/>
    </joint>
    <joint name="wheel_joint3">
      <command_interface name="velocity">
        <param name="min">-10.0</param>
        <param name="max">10.0</param>
      </command_interface>
      <state_interface name="position"/>
      <state_interface name="velocity"/>
    </joint>
    <joint name="wheel_joint4">
      <command_interface name="velocity">
        <param name="min">-10.0</param>
        <param name="max">10.0</param>
      </command_interface>
      <state_interface name="position"/>
      <state_interface name="velocity"/>
    </joint>

    # Position Controller
    <joint name="axle_joint1">
      <command_interface name="position">
        <param name="min">-0.6</param>
        <param name="max">0.6</param>
      </command_interface>
      <state_interface name="position"/>
      <state_interface name="velocity"/>
    </joint>
    <joint name="axle_joint3">
      <command_interface name="position">
        <param name="min">-0.6</param>
        <param name="max">0.6</param>
      </command_interface>
      <state_interface name="position"/>
      <state_interface name="velocity"/>
    </joint>
  </ros2_control>

  <gazebo>
    <plugin filename="libgazebo_ros2_control.so" name="gazebo_ros2_control">
      <parameters>$(find mobile_car)/config/control.yaml</parameters>
    </plugin>
  </gazebo>

  <gazebo reference="base_link">
    <xacro:base_link_color />
  </gazebo>
  <gazebo reference="lidar_link">
    <xacro:lidar_link_color />
  </gazebo>
  <gazebo reference="axle_link1">
    <xacro:axle_link_color />
  </gazebo>
  <gazebo reference="axle_link2">
    <xacro:axle_link_color />
  </gazebo>
  <gazebo reference="axle_link3">
    <xacro:axle_link_color />
  </gazebo>
  <gazebo reference="axle_link4">
    <xacro:axle_link_color />
  </gazebo>
  <gazebo reference="wheel_link1">
    <xacro:wheel_link_color />
  </gazebo>
  <gazebo reference="wheel_link2">
    <xacro:wheel_link_color />
  </gazebo>
  <gazebo reference="wheel_link3">
    <xacro:wheel_link_color />
  </gazebo>
  <gazebo reference="wheel_link4">
    <xacro:wheel_link_color />
  </gazebo>

</robot>